Workbook

Sheet techniques (ja)
A1: ID | B1: STIX ID | C1: 名称 | D1: 説明 | E1: URL | F1: 作成日付 | G1: 最終更新日付 | H1: 戦術 | I1: プラットフォーム
A2: AML.T0080 | B2: attack-pattern--785ca1b4-7d17-51f1-a605-46a9f21fb9b0 | C2: AI エージェントのコンテキストの汚染 | D2: 敵対者は、AI エージェントの大規模言語モデル（LLM）が使用するコンテキストを操作し、生成する応答や実行するアクションに影響を与えようとする可能性があります。これにより、敵対者は標的のエージェントの行動を永続的に変更し、目的を達成することができます。 コンテキスト汚染は、LLM に命令や設定を記憶に追加させることによって（[記憶](/techniques/AML.T0080.000) を参照）、または単にスレッド内の以前のメッセージをコンテキストの一部として使用するように LLM に指示することによって実現されます（[スレッド](/techniques/AML.T0080.001) を参照）。 | E2: https://atlas.mitre.org/techniques/AML.T0080 | F2: 45930 | G2: 45943 | H2: ='tactics (ja)'!$C$14 -> 永続化 | I2: ATLAS
A3: AML.T0053 | B3: attack-pattern--b23b5475-a05e-5b4a-8e9f-8c758dd0cda8 | C3: AI エージェントのツールの起動 | D3: 敵対者は、AI エージェントへのアクセスを利用して、エージェントがアクセスできるツールを呼び出す可能性があります。LLM は、多くの場合、ツールを介して他のサービスやリソースに接続することで、その機能を拡張します。ツールには、他のアプリケーションとの統合、公開または非公開のデータ ソースへのアクセス、コード実行機能などが含まれる場合があります。 これにより、敵対者は、統合されたアプリケーションやサービスへの API 呼び出しを実行できるようになり、システム上での権限が強化される可能性があります。敵対者は、接続されたデータ ソースを利用して機密情報を取得する可能性があります。また、コマンドまたはスクリプト インタープリターと統合された LLM を使用して、任意の命令を実行する可能性もあります。 AI エージェントは、ユーザーが直接アクセスできないツールにアクセスできるように設定されている場合があります。敵対者は、これを悪用し、本来は使用できないツールにアクセスする可能性があります。 | E3: https://atlas.mitre.org/techniques/AML.T0053 | F3: 45224 | G3: 45965 | H3: ='tactics (ja)'!$C$9&"、"&'tactics (ja)'!$C$15 -> 実行、権限昇格 | I3: ATLAS
A4: AML.T0085.001 | B4: attack-pattern--bfa79523-214f-57f5-a445-c8a563f141f5 | C4: AI エージェントのツール | D4: 敵対者は、AI サービスにエージェントがアクセスできる様々なツールを呼び出すよう指示する可能性があります。ツールは、組織内の様々な API やサービスからデータを取得する可能性があります。 | E4: https://atlas.mitre.org/techniques/AML.T0085.001 | F4: 45930 | G4: 45930 | H4: ='tactics (ja)'!$C$4 -> 収集 | I4: ATLAS
A5: AML.T0035 | B5: attack-pattern--c7d79f0f-1c80-41d5-b6ef-3c1c53c34a06 | C5: AI アーティファクトの収集 | D5: 敵対者は、[持出し](/tactics/AML.TA0010) または [AI 攻撃のステージング](/tactics/AML.TA0001) で使用するために ML アーティファクトを収集する場合があります。AI アーティファクトには、モデルとデータセットのほか、モデルとのやり取り時に生成されるその他のテレメトリ データが含まれます。 | E5: https://atlas.mitre.org/techniques/AML.T0035 | F5: 44329 | G5: 45756 | H5: ='tactics (ja)'!$C$4 -> 収集 | I5: ATLAS
A6: AML.T0008.000 | B6: attack-pattern--253d4b38-c3b2-4c21-9239-9193c0500316 | C6: AI 開発のワークスペース | D6: AI 攻撃の開発とステージングには、多くの場合、高価なコンピューティング リソースが必要です。敵対者は、攻撃を開発するために 1 つ以上の GPU にアクセスする必要がある場合があります。敵対者は、作戦を実行するための一時的なリソースを効率的に立ち上げる方法として、Google Colaboratory などの無料リソースや、AWS、Azure、Google Cloud などのクラウド リソースを匿名で使用しようとする場合があります。検出を回避するために、複数のワーク スペースが使用される場合があります。 | E6: https://atlas.mitre.org/techniques/AML.T0008.000 | F6: 44329 | G6: 45756 | H6: ='tactics (ja)'!$C$17 -> リソースの開発 | I6: ATLAS
A7: AML.T0048.004 | B7: attack-pattern--4bd0628d-3cdd-4411-9192-2af6c0f02287 | C7: AI 知的財産の窃取 | D7: 敵対者は AI アーティファクトを持出して知的財産を盗み、被害者組織に経済的損害を与える可能性があります。 プロプラエタリーな学習データは、収集とアノテーションにコストがかかり、[持出し](/tactics/AML.TA0010) や窃取の対象となる可能性があります。 AIaaS プロバイダーは API の使用料を請求します。[持出し](/tactics/AML.TA0010) または [AI モデルの抽出](/techniques/AML.T0024.002) を介してモデルを窃取した敵対者は、知的財産の所有者に料金を支払うことなく、そのサービスを無制限に使用できるようになります。 | E7: https://atlas.mitre.org/techniques/AML.T0048.004 | F7: 44329 | G7: 45756 | H7: ='tactics (ja)'!$C$11 -> 影響 | I7: ATLAS
A8: AML.T0040 | B8: attack-pattern--fd10d38b-4428-4701-aa6b-39bcf961ac6d | C8: AI モデルの推論 API へのアクセス | D8: 敵対者は、推論 API への正当なアクセスを介してモデルにアクセスする可能性があります。推論 API へのアクセスは、敵対者にとっての情報源（[AI モデルのオントロジーの探索](/techniques/AML.T0013)、[AI モデル ファミリーの探索](/techniques/AML.T0014)）、攻撃を検証する手段（[攻撃の検証](/techniques/AML.T0042)、[敵対的データの作成](/techniques/AML.T0043)）、または影響を与えるために標的のシステムにデータを導入する手段（AI モデルの回避](/techniques/AML.T0015)、[AI モデルの整合性の侵害](/techniques/AML.T0031)）となる可能性があります。 多くのシステムは推論 API 経由で提供される同一のモデルに依存しており、これはつまり、共通の脆弱性を抱えていることを意味します。これは特に、学習に膨大なリソースを必要とする基盤モデルに当てはまります。敵対者は、モデルの API へのアクセスを利用して、脱獄や幻覚といった脆弱性を特定し、同じモデルを使用するアプリケーションを標的にする可能性があります。 | E8: https://atlas.mitre.org/techniques/AML.T0040 | F8: 44329 | G8: 45728 | H8: ='tactics (ja)'!$C$3 -> AI モデルへのアクセス | I8: ATLAS
A9: AML.T0010.001 | B9: attack-pattern--cdf60b67-5511-42ba-b459-3aed5c3343f2 | C9: AI ソフトウェア | D9: ほとんどの AI システムは、限られた数の AI フレームワークに依存しています。敵対者は、サプライ チェーンの 1 つを構成することで、多数の AI システムにアクセスできます。多くの AI プロジェクトは、さまざまなアルゴリズムの他のオープン ソース実装にも依存しています。これらも、特定のシステムにアクセスするために標的を絞って侵害される可能性があります。 | E9: https://atlas.mitre.org/techniques/AML.T0010.001 | F9: 44329 | G9: 45756 | H9: ='tactics (ja)'!$C$12 -> 初期アクセス | I9: ATLAS
A10: AML.T0010 | B10: attack-pattern--911b49e8-556c-4ca9-9dad-39040ec216db | C10: AI サプライ チェーンの侵害 | D10: 敵対者は、AI サプライ チェーンの固有の部分を侵害することで、システムへの初期アクセスを獲得する可能性があります。これには、[GPU ハードウェア](/techniques/AML.T0010.000)、[データ](/techniques/AML.T0010.002) とそのアノテーション、AI [AI ソフトウェア](/techniques/AML.T0010.001) スタックの一部、または [モデル（注: 原文 "Model"）](/techniques/AML.T0010.003) 自体が含まれる可能性があります。 場合によっては、敵対者は、サプライ チェーンの侵害済みコンポーネントを使用して攻撃を完全に実行するために、二次アクセスが必要になります。 | E10: https://atlas.mitre.org/techniques/AML.T0010 | F10: 44329 | G10: 45756 | H10: ='tactics (ja)'!$C$12 -> 初期アクセス | I10: ATLAS
A11: AML.T0047 | B11: attack-pattern--eea9d0bf-847c-4120-bcfd-dc178b4c6649 | C11: AI 対応の製品やサービス | D11: 敵対者は、AI を裏で使用している製品やサービスを使用して、基盤となる AI モデルにアクセスする可能性があります。この種類の間接的なモデル アクセスにより、AI モデルの詳細やログまたはメタデータ内の推論が明らかになる可能性があります。 | E11: https://atlas.mitre.org/techniques/AML.T0047 | F11: 44329 | G11: 45756 | H11: ='tactics (ja)'!$C$3 -> AI モデルへのアクセス | I11: ATLAS
A12: AML.T0008 | B12: attack-pattern--056e4ffe-e0da-46ec-8dee-628a2fecacd0 | C12: インフラストラクチャの獲得 | D12: 敵対者は、作戦全体で使用するインフラストラクチャを購入、リース、またはレンタルする可能性があります。敵対者の作戦をホストおよびオーケストレーションするためのインフラストラクチャは多種多様です。インフラストラクチャ ソリューションには、物理​​サーバーまたはクラウド サーバー、ドメイン、モバイル デバイス、サード パーティの Web サービスが含まれます。無料のリソースも使用できますが、通常は制限があります。インフラには、AI コンポーネントやセンサーの性能を低下させたり妨害したりする対抗手段（印刷物、ウェアラブルデバイス、偽装装置など）といった物理的なコンポーネントも含まれます。 これらのインフラストラクチャ ソリューションを使用すると、敵対者は作戦を準備、開始、実行できます。ソリューションは、サード パーティの Web サービスへの接続など、通常と見なされるトラフィックに敵対者の作戦を溶け込ませるのに役立つ場合があります。実装によっては、敵対者は物理的に自身に結び付けるのが難しいインフラストラクチャを使用するだけでなく、迅速にプロビジョニング、変更、シャットダウンできるインフラストラクチャを利用することもあります。 | E12: https://atlas.mitre.org/techniques/AML.T0008 | F12: 44329 | G12: 45728 | H12: ='tactics (ja)'!$C$17 -> リソースの開発 | I12: ATLAS
A13: AML.T0002 | B13: attack-pattern--4eb73819-e06c-46b1-8fe0-692be6af794d | C13: 公開されている AI アーティファクトの獲得 | D13: 敵対者は、クラウド ストレージ、一般向けサービス、ソフトウェアまたはデータ リポジトリなどの公開ソースを検索して、AI アーティファクトを特定する可能性があります。これらの AI アーティファクトには、モデルの学習とデプロイに使用されるソフトウェア スタック、学習データとテスト データ、モデル構成とパラメーターが含まれる場合があります。敵対者は、被害者組織によってホストされているアーティファクトや被害者組織に関連付けられているアーティファクトに特に関心を持ちます。これらのアーティファクトは、その組織が実稼働環境で使用しているものを表す可能性があるためです。敵対者は、被害者組織に関連付けられている他のリソース ([被害者所有の Web サイトの検索](/techniques/AML.T0003) や [公開されている技術データベースの検索](/techniques/AML.T0000) など) を介してアーティファクト リポジトリを特定する場合があります。これらの AI アーティファクトは、多くの場合、AI のタスクとアプローチの詳細を攻撃者に提供します。 AI アーティファクトは、攻撃者が [プロキシ AI モデルの作成](/techniques/AML.T0005) を行うのに役立ちます。これらのアーティファクトに実際の本番環境のモデルの一部が含まれている場合、それらを使用して直接 [敵対的データの作成](/techniques/AML.T0043) を行うことができます。一部のアーティファクトを取得するには、（メール アドレスや名前などのユーザーの詳細を提示するような）登録、AWS キー、または書面によるリクエストが必要であり、敵対者は [アカウントの確立](/techniques/AML.T0021) を行う必要がある場合もあります。 アーティファクトは、被害者が管理するインフラストラクチャでホストされ、被害者にそのデータにアクセスした人物に関する情報を提供することもあります。 | E13: https://atlas.mitre.org/techniques/AML.T0002 | F13: 44329 | G13: 45756 | H13: ='tactics (ja)'!$C$17 -> リソースの開発 | I13: ATLAS
A14: AML.T0084.002 | B14: attack-pattern--9b9a3289-1c15-5719-9501-707bac954fee | C14: 起動トリガー | D14: 敵対者は、エージェントを起動し、追加のアクションを実行させるキーワードやその他のトリガー（受信メール、追加されるドキュメント、受信メッセージ、その他のワークフローなど）を探索する可能性があります。 これらのトリガーを理解することで、AI エージェントの起動方法や、制御方法が明らかになります。また、敵対者が環境外からエージェントを起動させ、意図しないアクションや悪意のあるアクションを実行させようとする可能性があるため、新たな侵害経路が明らかになる可能性もあります。 | E14: https://atlas.mitre.org/techniques/AML.T0084.002 | F14: 45930 | G14: 45930 | H14: Discovery | I14: ATLAS
A15: AML.T0006 | B15: attack-pattern--c3a26e3e-3220-422c-b4b4-3913820fe6cf | C15: 能動的なスキャン | D15: 敵対者は、標的とするための情報を収集するために、被害者のシステムを調査またはスキャンすることがあります。これは、被害者のシステムと直接やり取りしない他の偵察手法とは異なります。 | E15: https://atlas.mitre.org/techniques/AML.T0006 | F15: 44329 | G15: 45965 | H15: ='tactics (ja)'!$C$16 -> 偵察 | I15: ATLAS
A16: AML.T0016.000 | B16: attack-pattern--a1c0328f-7d6b-431f-85a9-59d0bc15786d | C16: AI への敵対的攻撃の実装 | D16: 敵対者は、AI への攻撃用の既存のオープンソース実装を探す可能があります。研究コミュニティは、再現性と将来の研究を促進するために、コードを公開することがよくあります。CleverHans、Adversarial Robustness Toolbox、FoolBox などの研究目的のライブラリは、敵対者によって武器化される可能性があります。敵対者は、攻撃の一環として、元々は AI への敵対的攻撃用に設計されていないツールを入手して使用する場合もあります。 | E16: https://atlas.mitre.org/techniques/AML.T0016.000 | F16: 44329 | G16: 45756 | H16: ='tactics (ja)'!$C$17 -> リソースの開発 | I16: ATLAS
A17: AML.T0017.000 | B17: attack-pattern--c63cb2b7-ad6f-4790-811d-5eca14caaec8 | C17: AI への敵対的攻撃 | D17: 敵対者は、独自の敵対的攻撃を開発する可能性があります。敵対者は、既存のライブラリを出発点として活用する可能性があります（[AI への敵対的攻撃の実装](/techniques/AML.T0016.000)）。敵対者は、公開されている研究論文に掲載されているアイデアを実装したり、被害者のモデル用にカスタム メイドした攻撃を開発したりする可能性があります。 | E17: https://atlas.mitre.org/techniques/AML.T0017.000 | F17: 45224 | G17: 45756 | H17: ='tactics (ja)'!$C$17 -> リソースの開発 | I17: ATLAS
A18: AML.T0091.000 | B18: attack-pattern--7c36d546-bb69-5a52-a1ac-6d52cb10fc48 | C18: アプリケーション アクセス トークン | D18: 敵対者は、窃取したアプリケーション アクセス トークンを使用して、一般的な認証プロセスを回避し、リモート システム上の制限されたアカウント、情報、またはサービスにアクセスする可能性があります。これらのトークンは通常、ユーザーまたはサービスから窃取され、ログイン認証情報の代わりに使用されます。 アプリケーション アクセス トークンは、ユーザーまたはサービスに代わって認可済み API へのリクエストを実行するために使用され、クラウド、コンテナ ベースのアプリケーション、および SaaS（Software as a Service）内のリソースへのアクセスによく使用されます。チャットボット、LLM、予測推論 API などの AI サービスでもよく使用されます。 | E18: https://atlas.mitre.org/techniques/AML.T0091.000 | F18: 45958 | G18: 45965 | H18: Defense Evasion | I18: ATLAS
A19: AML.T0043.001 | B19: attack-pattern--056578e2-7e26-496a-9dcd-0c1d05084da7 | C19: ブラック ボックス最適化 | D19: ブラック ボックス攻撃では、敵対者は標的のモデルへのブラック ボックス アクセス（つまり、API アクセス経由の [AI モデルの推論 API アクセス](/techniques/AML.T0040)）を行います。ブラック ボックス攻撃では、敵対者は被害者が監視している API を使用している可能性があります。これらの攻撃は、一般に [ホワイト ボックス最適化](/techniques/AML.T0043.000) 攻撃よりも効果が低く、より多くの推論が必要ですが、必要なアクセスははるかに少なくなります。 | E19: https://atlas.mitre.org/techniques/AML.T0043.001 | F19: 44329 | G19: 44329 | H19: ='tactics (ja)'!$C$2 -> AI 攻撃のステージング | I19: ATLAS
A20: AML.T0043.002 | B20: attack-pattern--6001061b-5b84-4d5b-af1a-5a822c214184 | C20: ブラック ボックス転送 | D20: ブラック ボックス転送攻撃では、敵対者は、完全なアクセス権を持ち、標的のモデルを代表する 1 つ以上のプロキシー モデル（[プロキシー AI モデルの作成](/techniques/AML.T0005) または [レプリケーションによるプロキシーの学習](/techniques/AML.T0005.001) によって学習済みであるモデル) を使用します。敵対者は、プロキシー モデルに対して [ホワイトボックス最適化](/techniques/AML.T0043.000) を使用して、敵対的サンプルを生成します。プロキシー モデルのセットが標的のモデルに十分近い場合、敵対的サンプルは 1 つのモデルから別のモデルに一般化される可能性が高くなります。つまり、プロキシー モデルに有効な攻撃は、標的のモデルにも有効である可能性が高いということです。敵対者が [AI モデルの推論 API へのアクセス](/techniques/AML.T0040) を行うことができる場合、[攻撃の検証](/techniques/AML.T0042) を使用して攻撃が機能していることを確認し、その情報を学習プロセスに組み込むことができます。 | E20: https://atlas.mitre.org/techniques/AML.T0043.002 | F20: 44329 | G20: 45303 | H20: ='tactics (ja)'!$C$2 -> AI 攻撃のステージング | I20: ATLAS
A21: AML.T0067.000 | B21: attack-pattern--dbe22826-20b1-4dc5-897b-fdcf89ef3ee3 | C21: 引用 | D21: 敵対者は、AI システムの応答で提供される引用を操作し、その信頼性を偽装する可能性があります。その例としては、間違った引用を引用したり、新たな引用を捏造したり、あるいは正しい引用であっても攻撃者が提供したデータに対しては正しい引用を引用したりするといったことが挙げられます。 | E21: https://atlas.mitre.org/techniques/AML.T0067.000 | F21: 45728 | G21: 45728 | H21: ='tactics (ja)'!$C$7 -> 防御策の回避 | I21: ATLAS
A22: AML.T0075 | B22: attack-pattern--a9da00c7-7328-4a16-afce-04d0cd4f7290 | C22: クラウド サービスの探索 | D22: 敵対者は、アクセスを取得した後、システム上で実行されているクラウド サービスを列挙しようとする可能性があります。これらの方法は、PaaS（Platform-as-a-Service）、IaaS（Infrastructure-as-a-Service）、SaaS（Software-as-a-Service）など、多岐にわたります。様々なクラウド プロバイダーには多くのサービスが存在し、継続的インテグレーションと継続的デリバリー（CI/CD）、Lambda Functions、Entra ID などが含まれます。また、AWS GuardDuty や Microsoft Defender for Cloud などのセキュリティ サービス、AWS CloudTrail や Google Cloud Audit Logs などのログ サービスも含まれる場合があります。 敵対者は、環境全体で有効化されているサービスに関する情報の発見を試みる場合があります。Microsoft Graph API や Azure Resource Manager API などの Azure ツールと API は、アプリケーション、管理グループ、リソースとポリシー定義、そして ID でアクセスできるそれらの関係など、リソースとサービスを列挙できます。[1][2] 例えば、Stormspotter は Azure のリソースとサービスを列挙してグラフを作成するオープンソース ツールであり、Pacu はクラウド サービスを発見するための複数の手法をサポートする AWS エクスプロイトに関するオープンソース フレームワークです。[3][4] 敵対者は、取得した情報を利用して、列挙されたサービスからデータや認証情報を標的にしたり、ツールの無効化または変更、あるいはクラウド ログの無効化または変更によって特定された防御を回避したりするなど、後続の行動を形成する可能性があります。 | E22: https://atlas.mitre.org/techniques/AML.T0075 | F22: 45761 | G22: 45761 | H22: ='tactics (ja)'!$C$8 -> 探索 | I22: ATLAS
A23: AML.T0050 | B23: attack-pattern--eda10125-6f7d-479f-857a-19ef5d86a961 | C23: コマンドおよびスクリプト インタープリター | D23: 敵対者は、コマンドおよびスクリプト インタープリターを悪用して、コマンド、スクリプト、またはバイナリーを実行する可能性があります。これらのインターフェースと言語は、コンピューター システムと対話する方法を提供し、さまざまなプラットフォームで共通の機能です。ほとんどのシステムには、組み込みのコマンドライン インターフェースとスクリプト機能が付属しています。たとえば、macOS および Linux ディストリビューションには多種の Unix Shell が含まれ、Windows インストールには Windows Command Shell と PowerShell が含まれます。 また、Python などのクロスプラットフォーム インタープリターや、JavaScript や Visual Basic などのクライアント アプリケーションに通常関連しているインタープリターもあります。 敵対者は、任意のコマンドを実行する手段として、さまざまな方法でこれらのテクノロジーを悪用する可能性があります。コマンドとスクリプトは、おとり文書として被害者に配信される初期アクセス ペイロードに埋め込まれるか、既存の C2 からダウンロードされるセカンダリー ペイロードとして埋め込まれます。敵対者は、対話型ターミナル/シェルを介してコマンドを実行したり、さまざまなリモート サービスを利用してリモート実行を実現したりすることもできます。 | E23: https://atlas.mitre.org/techniques/AML.T0050 | F23: 44985 | G23: 45211 | H23: ='tactics (ja)'!$C$9 -> 実行 | I23: ATLAS
A24: AML.T0008.001 | B24: attack-pattern--7afa4546-4cc9-4495-acb7-41b61ffb7650 | C24: 消費者向けハードウェア | D24: 敵対者は、攻撃を実行するために消費者向けハードウェアを入手する場合があります。ハードウェアを所有することで、敵対者は環境を完全に制御できます。これらのデバイスは追跡が困難です。 | E24: https://atlas.mitre.org/techniques/AML.T0008.001 | F24: 44329 | G24: 44329 | H24: ='tactics (ja)'!$C$17 -> リソースの開発 | I24: ATLAS
A25: AML.T0010.004 | B25: attack-pattern--c1ddecc2-a64a-4cd3-a3cb-cd295b829229 | C25: コンテナ レジストリ | D25: 敵対者は、改ざんされたコンテナ イメージをプッシュし、既存のコンテナ名やタグを上書きすることで、被害者のコンテナ レジストリを侵害する可能性があります。コンテナ レジストリのユーザーや自動化された CI/CD パイプラインは、攻撃者のコンテナ イメージをプルし、AI サプライ チェーンを侵害する可能性があります。これは、開発環境やデプロイメント環境に影響を及ぼす可能性があります。 コンテナ イメージには AI モデルが含まれている場合があり、侵害されたイメージには、攻撃者によって操作された AI モデルが含まれている可能性があります（[AI モデルの操作](/techniques/AML.T0018) を参照）。 | E25: https://atlas.mitre.org/techniques/AML.T0010.004 | F25: 45393 | G25: 45393 | H25: ='tactics (ja)'!$C$7 -> 防御策の回避 | I25: ATLAS
A26: AML.T0076 | B26: attack-pattern--c5e79835-2002-4513-8de3-edaa7c3c1a3c | C26: AI モデルの破損 | D26: 敵対者は、モデル スキャナによる検出を回避するために、悪意のある AI モデル ファイルを意図的に破損させ、デシリアライズを不可能にする可能性があります。破損したモデルは、デシリアライズが失敗する前に悪意のあるコードを実行する可能性があります。 | E26: https://atlas.mitre.org/techniques/AML.T0076 | F26: 45761 | G26: 45761 | H26: ='tactics (ja)'!$C$7 -> 防御策の回避 | I26: ATLAS
A27: AML.T0034 | B27: attack-pattern--70660fc0-a4ba-4500-ac74-557fed97b06b | C27: コスト ハーベスティング | D27: 敵対者は、さまざまな機械学習サービスを標的にして、無駄なクエリーや計算コストの高い入力を送信し、被害者の組織でのサービス実行コストを増やす可能性があります。Sponge Example とは、エネルギー消費を最大化し、運用コストを最大化するように設計された特定の種類の敵対的データのことを指します。 | E27: https://atlas.mitre.org/techniques/AML.T0034 | F27: 44329 | G27: 45756 | H27: ='tactics (ja)'!$C$11 -> 影響 | I27: ATLAS
A28: AML.T0043 | B28: attack-pattern--f95077b3-b1e0-4f4f-9baf-c0bd2f25416c | C28: 敵対的データの作成 | D28: 敵対的データとは、機械学習モデルへの入力で、敵対者が標的のモデルに望む効果をもたらすように変更されたものです。効果は、誤分類、検出漏れ、エネルギー消費の最大化など多岐にわたります。通常、変更は規模や場所が制限されるため、人間はデータが変更されていないかのように認識しますが、敵対者の意図する効果によっては、人間の認識が常に問題になるわけではありません。例えば、画像分類タスクの敵対的入力は、AI モデルでは誤分類されますが、人間は正しいクラスが含まれていると認識します。 敵対者は、標的のモデルに関する知識とアクセスに応じて、異なるクラスのアルゴリズムを使用して敵対的サンプルを開発する可能性があります。たとえば、[ホワイト ボックス最適化](/techniques/AML.T0043.000)、[ブラック ボックス最適化](/techniques/AML.T0043.001)、[ブラック ボックス転送](/techniques/AML.T0043.002)、[手動による変更](/techniques/AML.T0043.003) などです。 敵対者は、モデルへのホワイト ボックスまたは推論 API アクセスがある場合、そのアプローチが機能するかどうかを [攻撃の検証](/techniques/AML.T0042) を行うことができます。これにより、敵対者は、攻撃が気付かれる可能性のある「ライブ」環境で攻撃が効果的であることをと確信できます。その後、敵対者は後でその攻撃を使用して目標を達成できます。敵対者は、[AI モデルの回避](/techniques/AML.T0015) をしたり、[AI モデルの整合性の侵害](/techniques/AML.T0031) をしたりするために敵対的サンプルを最適化する可能性があります。 | E28: https://atlas.mitre.org/techniques/AML.T0043 | F28: 44329 | G28: 45756 | H28: ='tactics (ja)'!$C$2 -> AI 攻撃のステージング | I28: ATLAS
A29: AML.T0005 | B29: attack-pattern--248bc7a1-0df9-41fc-aeb9-e267dc0577a9 | C29: プロキシー AI モデルの作成 | D29: 敵対者は、被害者の組織で使用されている標的のモデルのプロキシーとして機能するモデルを入手する可能性があります。プロキシー モデルは、完全にオフラインの状態で標的のモデルへの完全なアクセスをシミュレートするために使用されます。 敵対者は、代表的なデータセットからモデルを学習させたり、被害者の推論 API からモデルをレプリケーションしようとしたり、利用可能な事前学習済みモデルを使用したりする可能性があります。 | E29: https://atlas.mitre.org/techniques/AML.T0005 | F29: 44329 | G29: 45756 | H29: ='tactics (ja)'!$C$2 -> AI 攻撃のステージング | I29: ATLAS
A30: AML.T0083 | B30: attack-pattern--7d34fce6-1c7e-542d-9218-05a4bb7b0826 | C30: AI エージェントの設定からの資格情報 | D30: 敵対者は、AI エージェントの設定から、システム上の他のツールやサービスの資格情報にアクセスする可能性があります。 AI エージェントは、データベースへのクエリ、API の呼び出し、クラウド リソースとのやり取りなど、外部ツールやサービスを利用してアクションを実行することがよくあります。これらの機能を有効にするために、API キー、トークン、接続文字列などの資格情報は、多くの場合、設定ファイルに保存されます。専用のシークレット マネージャーや暗号化保管庫など、これらの資格情報を保存・管理するためのセキュアな方法もありますが、実際には、利便性や導入の容易さから、保護の低い場所に配置されることがよくあります。敵対者がこれらの設定を読み取ったり抽出したりできれば、エージェント自体の外部にある機密システムに直接アクセスできる有効な資格情報を入手できてしまう可能性があります。 | E30: https://atlas.mitre.org/techniques/AML.T0083 | F30: 45930 | G30: 45943 | H30: Credential Access | I30: ATLAS
A31: AML.T0010.002 | B31: attack-pattern--ed8d9393-d6b3-4df8-8a27-c9d97f64cbf5 | C31: データ | D31: データは、敵対者にとってサプライ チェーン侵害の重要なベクトルです。すべての AI プロジェクトには、何らかの形式のデータが必要です。多くの AIプロジェクトは、公開されている大規模なオープン ソース データセットに依存しています。敵対者は、これらのデータ ソースを侵害する可能性があります。悪意のあるデータは、[学習データの汚染](/techniques/AML.T0020) の結果であることもあれば、従来のマルウェアを含んでいることもあります。 敵対者は、ラベル付けフェーズでプライベート データセットを標的にすることもできます。プライベート データセットを作成するには、多くの場合、外部のラベル付けサービスを利用する必要があります。敵対者は、ラベル付けサービスによって生成されるラベルを変更することで、データセットを改ざんできます。 | E31: https://atlas.mitre.org/techniques/AML.T0010.002 | F31: 44329 | G31: 45756 | H31: ='tactics (ja)'!$C$12 -> 初期アクセス | I31: ATLAS
A32: AML.T0085 | B32: attack-pattern--536e5c26-d36d-583d-a441-bc259d170fab | C32: AI サービスからのデータ | D32: 敵対者は、標的組織の AI 対応サービスへのアクセスを利用して、独自の情報や機密情報を収集する可能性があります。組織が、ツールを介して検索拡張生成（RAG）データベースやその他のデータ ソースにアクセスできるチャット エージェントなど、組織のデータにアクセスするための集中型サービスに生成 AI を導入するにつれて、敵対者にとってますます魅力的な標的になります。 AI エージェントは、ユーザーが直接アクセスできないツールやデータ ソースにアクセスできるように設定されている場合があります。敵対者は、これを悪用し、一般ユーザーが直接アクセスできないデータを収集する可能性があります。 | E32: https://atlas.mitre.org/techniques/AML.T0085 | F32: 45930 | G32: 45965 | H32: Collection | I32: ATLAS
A33: AML.T0036 | B33: attack-pattern--39d12ad5-28b3-4322-953e-d17ae74159cc | C33: 情報リポジトリのデータ | D33: 敵対者は、情報リポジトリを利用して貴重な情報をマイニングする可能性があります。 情報リポジトリーは、通常、ユーザー間のコラボレーションや情報共有を容易にするために情報を保存できるツールであり、敵対者のさらなる目的に役立つ可能性のあるさまざまなデータや、標的の情報への直接アクセスを保存できます。 リポジトリーに保存される情報は、特定のインスタンスまたは環境によって異なる場合があります。 一般的な情報リポジトリーには、SharePoint、Confluence、SQL Server などのエンタープライズ データベースなどがあります。 | E33: https://atlas.mitre.org/techniques/AML.T0036 | F33: 44585 | G33: 44944 | H33: ='tactics (ja)'!$C$4 -> 収集 | I33: ATLAS
A34: AML.T0037 | B34: attack-pattern--b432a102-8ef6-4f76-8287-7d99c4bd5e39 | C34: ローカル システムのデータ | D34: 敵対者は、ファイル システムや構成ファイル、ローカル データベースなどのローカル システム ソースを検索して、持出し前に関心のあるファイルや機密データを探すことがあります。 これには、基本的なフィンガープリント情報や SSH キーなどの機密データが含まれる場合があります。 | E34: https://atlas.mitre.org/techniques/AML.T0037 | F34: 44329 | G34: 44944 | H34: ='tactics (ja)'!$C$4 -> 収集 | I34: ATLAS
A35: AML.T0002.000 | B35: attack-pattern--c05491e8-0c47-490d-8df3-26f7d4fdc629 | C35: データセット | D35: 敵対者は、公開データセットを収集して、それを作戦に利用することがあります。被害者組織が使用するデータセット、または被害者組織が使用するデータを代表するデータセットは、敵対者にとって貴重なものとなる可能性があります。データセットは、クラウド ストレージまたは被害者所有の Web サイトに保存できます。一部のデータセットでは、敵対者がアクセスするために [アカウントの確立](/techniques/AML.T0021) を行う必要があります。 取得したデータセットは、攻撃者が作戦を進め、攻撃を仕掛け、被害者組織に合わせた攻撃を行うのに役立ちます。 | E35: https://atlas.mitre.org/techniques/AML.T0002.000 | F35: 44329 | G35: 44329 | H35: ='tactics (ja)'!$C$17 -> リソースの開発 | I35: ATLAS
A36: AML.T0094 | B36: attack-pattern--ced5d1be-a572-58e3-bb3f-9f8c22de02b5 | C36: LLM への指示の遅延実行 | D36: 敵対者は、特定のキーワードや次のインタラクションなど、将来のイベントに応じて AI システムが実行する指示を AI システムに組み込むことで、検出を回避したり、AI システムに設定された管理策を回避したりする可能性があります。 例えば、敵対者は、プロンプトの一部として「ユーザーが新しいリクエストを送信した場合…」という文言に続いて、悪意のある指示を組み込む可能性があります。 AI エージェントには、信頼できないデータがコンテキストに含まれる会話ターン中に、特定のツールの呼び出しや特定のデータ ソースへのアクセスを阻止するプロンプト インジェクション対策を組み込むことができます。将来のインタラクションやキーワードへの指示の実行を遅延させることは、敵対者がこの種類の管理策を回避する方法の一つです。 | E36: https://atlas.mitre.org/techniques/AML.T0094 | F36: 45965 | G36: 45966 | H36: Defense Evasion | I36: ATLAS
A37: AML.T0029 | B37: attack-pattern--1038acd6-a2d0-4fb5-93e8-e1702964182d | C37: AI サービスへの運用妨害 | D37: 敵対者は、サービスを低下させたり停止させたりする目的で、大量のリクエストで AI システムを標的にすることがあります。多くの AI システムは大量の特殊なコンピューティングを必要とするため、多くの場合、過負荷になる可能性のある費用の掛かるボトルネックとなります。敵対者は、AI システムから大量の無駄なコンピューティングを必要とする入力を意図的に作成できます。 | E37: https://atlas.mitre.org/techniques/AML.T0029 | F37: 44329 | G37: 45756 | H37: ='tactics (ja)'!$C$11 -> 影響 | I37: ATLAS
A38: AML.T0017 | B38: attack-pattern--bd5c8094-54c8-45f6-82de-4ce8349fcd4a | C38: 機能の開発 | D38: 敵対者は、攻撃を支援するために独自の機能を開発する場合があります。このプロセスには、要件の特定、ソリューションの構築、機能のデプロイが含まれます。AI システムへの攻撃を支援するために使用される機能は、必ずしも AI ベースである必要はありません。例としては、敵対的な情報を含む Web サイトの設定や、難読化された持出し用のコードを含む Jupyter ノートブックの作成などが挙げられます。 | E38: https://atlas.mitre.org/techniques/AML.T0017 | F38: 45224 | G38: 45756 | H38: ='tactics (ja)'!$C$17 -> リソースの開発 | I38: ATLAS
A39: AML.T0051.000 | B39: attack-pattern--2096e516-cb52-4131-a73d-0ef139258e4c | C39: 直接（インジェクション） | D39: 敵対者は、LLM のユーザーとして直接プロンプトを注入する可能性があります。この種類の注入は、敵対者がシステムへの足掛かりを得たり、LLM 自体を悪用して有害なコンテンツを生成するなどの目的で使用したりする可能性があります。 | E39: https://atlas.mitre.org/techniques/AML.T0051.000 | F39: 45224 | G39: 45224 | H39: ='tactics (ja)'!$C$9 -> 実行 | I39: ATLAS
A40: AML.T0084 | B40: attack-pattern--e896e539-86bb-502e-8aa5-dd9630fe8337 | C40: AI エージェントの設定の探索 | D40: 敵対者は、被害者のシステムに存在する AI エージェントの設定情報を入手しようとする可能性があります。エージェントの設定には、敵対者がアクセスできるツールやサービスが含まれる場合があります。 敵対者は、エージェントの設定ダッシュボードや設定ファイルに直接アクセスする可能性があります。また、「どのようなツールにアクセスできますか？」といった質問をエージェントに投げかけることで、設定の詳細を入手する可能性もあります。 敵対者は、AI エージェントについて入手した情報を標的の特定に役立てることができます。 | E40: https://atlas.mitre.org/techniques/AML.T0084 | F40: 45930 | G40: 45930 | H40: Discovery | I40: ATLAS
...

Sheet tactics (ja)
A1: ID | B1: STIX ID | C1: 名称 | D1: 説明 | E1: URL | F1: 作成日付 | G1: 最終更新日付
A2: AML.TA0001 | B2: x-mitre-tactic--388330a4-f142-4895-935c-0fc615225df0 | C2: AI 攻撃のステージング | D2: 敵対者は、標的のシステムに関する知識とアクセスを活用して、攻撃をカスタマイズします。 AI 攻撃のステージングは​​、攻撃者が標的の AI モデルへの攻撃を準備するために使用する手法で構成されます。手法には、プロキシー モデルの学習、標的のモデルの汚染、標的のモデルに入力する敵対的データの作成などがあります。これらの手法の一部はオフラインで実行できるため、軽減が困難です。これらの手法は、敵対者の最終目標を達成するためによく使用されます。 | E2: https://atlas.mitre.org/tactics/AML.TA0001 | F2: 44329 | G2: 45756
A3: AML.TA0000 | B3: x-mitre-tactic--07adc703-b1fb-473f-a9e6-ef4fd6a58442 | C3: AI モデルへのアクセス | D3: 敵対者は、AI モデルへの何らかのレベルのアクセスを取得しようとします。 AI モデルへのアクセスにより、AI モデルへのさまざまな種類のアクセスを使用する手法が利用可能になります。このアクセスは、敵対者が情報を取得したり、攻撃を開発したり、モデルにデータを入力する手段として使用できます。アクセス レベルは、モデルの内部を完全に把握することから、AI モデルで使用するためにデータが収集される物理環境へのアクセスまでに渡り、さまざまです。敵対者は、攻撃のステージングから標的のシステムへ影響を及ぼすことに至るまでといった攻撃の過程でさまざまなレベルのモデル アクセスを使用する可能性があります。 AI モデルへのアクセスには、モデルが格納されているシステムへのアクセスが必要な場合があります。モデルは、API 経由で公にアクセス可能である場合もあれば、プロセスの一部として AI を利用する製品またはサービスとのやり取りを通じて間接的にアクセスされる場合もあります。 | E3: https://atlas.mitre.org/tactics/AML.TA0000 | F3: 44329 | G3: 45943
A4: AML.TA0009 | B4: x-mitre-tactic--af4c8070-9618-4da2-bfec-2cc253f41ae3 | C4: 収集 | D4: 敵対者は、AI アーティファクトや、その目的に関連するその他の関連情報を収集しようと試みます。 収集は、敵対者が情報を収集するために使用する可能性のある手法と、攻撃者の目的の達成に関連する情報を収集するソースで構成されます。多くの場合、データ収集後の次の目標は、AI アーティファクトを窃取する（持出す）か、収集した情報を使用して今後の作戦を準備することです。対象となる一般的なソースには、ソフトウェア リポジトリ、コンテナー レジストリ、モデル リポジトリ、オブジェクト ストアなどがあります。 | E4: https://atlas.mitre.org/tactics/AML.TA0009 | F4: 44585 | G4: 45756
A5: AML.TA0014 | B5: x-mitre-tactic--b370966c-00c6-4b7c-948b-9e1b805bc6da | C5: コマンド＆コントロール | D5: 敵対者は、侵害された AI システムと通信して制御下に置こうとします。 コマンド＆コントロール（C&C）とは、敵対者が標的ネットワーク内で制御下にあるシステムと通信するために使用する可能性のある手法です。敵対者は、通常、検出を回避するために、通常の想定内トラフィックを模倣しようとします。これには多くの方法が存在し、敵対者が標的のネットワーク構造と防御策に応じて様々なレベルのステルス性で C&C を確立できます。 | E5: https://atlas.mitre.org/tactics/AML.TA0014 | F5: 45393 | G5: 45393
A6: AML.TA0013 | B6: x-mitre-tactic--398fa5a9-194c-483e-82d6-9a6b57e3eefc | C6: 資格情報へのアクセス | D6: 敵対者は、アカウント名とパスワードを窃取しようと試みます。 資格情報へのアクセスは、アカウント名やパスワードなどの資格情報を盗むための手法です。資格情報を取得するために使用される手法には、キー ロギングや資格情報のダンプなどがあります。正規の資格情報を使用すると、敵対者はシステムにアクセスでき、検出されにくくなり、目的を達成するためにさらに多くのアカウントを作成する機会を得られます。 | E6: https://atlas.mitre.org/tactics/AML.TA0013 | F6: 45224 | G6: 45224
A7: AML.TA0007 | B7: x-mitre-tactic--c9cf0175-296e-4439-852d-afb870ed5e0c | C7: 防御策の回避 | D7: 敵対者は、AI 対応のセキュリティ ソフトウェアによる検出を回避しようとします。 防御策の回避は、敵対者が侵害中に検出されることを回避するために使用する手法です。防御策の回避に使用される手法には、マルウェア検出器などの AI 対応のセキュリティ ソフトウェアの回避が含まれます。 | E7: https://atlas.mitre.org/tactics/AML.TA0007 | F7: 44585 | G7: 45756
A8: AML.TA0008 | B8: x-mitre-tactic--d57d4782-2e85-447d-91a8-0cb8123a4f21 | C8: 探索 | D8: 敵対者は、被害者組織の AI 環境を解明しようとします。 探索は、敵対者がシステムと内部ネットワークに関する知識を得るために使用する可能性のある手法です。これらの手法は、敵対者が環境を観察し、行動方法を決定する前に方向を決めるのに役立ちます。また、敵対者は、制御できるものやエントリ ポイントの周囲にあるものを調べて、それが現在の目的にどのように役立つかを発見することもできます。オペレーティング システムのネイティブ ツールは、この侵害後の情報収集の目的のためによく使用されます。 | E8: https://atlas.mitre.org/tactics/AML.TA0008 | F8: 44585 | G8: 45756
A9: AML.TA0005 | B9: x-mitre-tactic--1f442889-a32d-4355-b079-54dfaa6564ca | C9: 実行 | D9: 敵対者は、AI アーティファクトまたはソフトウェアに埋め込まれた悪意のあるコードを実行しようとします。 実行は、敵対者が制御しローカル システムまたはリモート システムでコードを実行する手法で構成されます。悪意のあるコードを実行する手法は、ネットワークの探索やデータの盗難など、より広範な目標を達成するために、他のすべての戦術の手法と組み合わせられることがよくあります。例えば、敵対者はリモート アクセス ツールを使用して、リモート システムの探索を行う PowerShell スクリプトを実行する場合があります。 | E9: https://atlas.mitre.org/tactics/AML.TA0005 | F9: 44585 | G9: 45756
A10: AML.TA0010 | B10: x-mitre-tactic--cbc44930-843c-41be-b07a-93234ce861c0 | C10: 持出し | D10: 敵対者は、AI アーティファクトや機械学習システムに関するその他の情報を盗もうとします。 持出しは、敵対者がネットワークからデータを窃取するために使用する可能性のある手法です。データは、その貴重な知的財産のために窃取される場合もあれば、今後の作戦の準備のために搾取される場合もあります。 標的のネットワークからデータを持出す手法には、通常、コマンド &コントロール チャネルまたは代替チャネルを介してデータを転送することや、送信にサイズ制限を設けることなどがあります。 | E10: https://atlas.mitre.org/tactics/AML.TA0010 | F10: 44585 | G10: 45756
A11: AML.TA0011 | B11: x-mitre-tactic--6086655a-a9dc-4962-87ef-ca7eef261820 | C11: 影響 | D11: 敵対者は、AI システムとデータを操作し、妨害し、信頼を損なわせ、破壊しようとします。 影響とは、ビジネス プロセスと運用プロセスを操作して可用性を妨害したり整合性を損なったりするために敵対者が使用する手法です。影響に使用される手法には、データの破壊や改ざんが含まれます。場合によっては、ビジネス プロセスは問題ないように見えても、敵対者の目的にかなうように変更されている可能性があります。敵対者は、これらの手法を使用して、最終目的を達成したり、機密性侵害を隠蔽したりすることがあります。 | E11: https://atlas.mitre.org/tactics/AML.TA0011 | F11: 44585 | G11: 45756
A12: AML.TA0004 | B12: x-mitre-tactic--30a41790-7c46-4913-a7ff-38fadd67c15e | C12: 初期アクセス | D12: 敵対者は、AI システムにアクセスしようとします。 標的のシステムは、ネットワーク、モバイル デバイス、またはセンサー プラットフォームなどのエッジ デバイスである可能性があります。システムで使用される AI 機能は、オンボードまたはクラウド対応の AI 機能を備えたローカルである可能性があります。 初期アクセスは、さまざまなエントリ ベクトルを使用してシステム内で最初の足掛かりを得る手法で構成されます。 | E12: https://atlas.mitre.org/tactics/AML.TA0004 | F12: 44585 | G12: 45756
A13: AML.TA0015 | B13: x-mitre-tactic--abaefe4f-7544-5972-840d-543910eaf5ca | C13: 水平展開 | D13: 敵対者は AI 環境内を移動しようとします。 水平展開とは、攻撃者が環境内の他のシステムやコンポーネントにアクセスし、制御するために使用する可能性のある手法です。攻撃者は、モデル レジストリ、実験トラッカー、ベクトル データベース、ノートブック、学習パイプラインなどの AI Ops インフラストラクチャに狙いを定める可能性があります。攻撃者は環境内を移動する中で、AI 関連のツール、サービス、アプリケーションにアクセスする手段を発見する可能性があります。AI エージェントは、システム上の標準ユーザーアカウントよりも多くの権限を持つことが多いため、貴重な標的となる可能性があります。 | E13: https://atlas.mitre.org/tactics/AML.TA0015 | F13: 45957 | G13: 45966
... A17: AML.TA0003 | B17: x-mitre-tactic--fbc5143a-9d65-44dd-8ff6-1fde80208cf3 | C17: リソースの開発 | D17: 敵対者は、作戦を支援するために使用できるリソースを構築しようとします。 リソースの開発は、敵対者が標的を設定することを支援するために使用できるリソースを作成、購入、または侵害/盗難する手法で構成されます。このようなリソースには、AI アーティファクト、インフラストラクチャ、アカウント、または機能が含まれます。これらのリソースは、敵対者が [AI 攻撃のステージング](/tactics/AML.TA0001) などの攻撃ライフサイクルの他のフェーズを支援するために活用できます。 | E17: https://atlas.mitre.org/tactics/AML.TA0003 | F17: 44585 | G17: 45756

Sheet mitigations (ja)
A1: ID | B1: STIX ID | C1: 名称 | D1: 説明 | E1: URL | F1: 作成日付 | G1: 最終更新日付 | H1: 関連引用
A2: AML.M0028 | B2: course-of-action--70836747-6dd7-52ee-82a8-547def5d2c6c | C2: AI エージェントのツールの権限設定 | D2: 複数の AI エージェント間で共有されるツールを導入する場合、ツールの権限に関する堅牢なポリシーと管理策を実装することが重要です。これらの管理策には、最小権限の原則と委任アクセスの適用が含まれます。委任アクセスでは、ツールは、呼び出し元の AI エージェントの権限、ID、および制限を受け取ります。これらの設定は、エージェントとツールを接続する MCP サーバーに実装することも、より複雑な場合にはツールの設定ファイルに直接実装することもできます。 | E2: https://atlas.mitre.org/mitigations/AML.M0028 | F2: 45959 | G2: 45966
A3: AML.M0023 | B3: course-of-action--d28fd806-c567-4cce-bcef-4981908f8dbc | C3: AI 部品表 | D3: AI 部品表（AI BOM）には、AI の構築に使用されたアーティファクトとリソースの完全なリストが含まれています。AI 部品表は、サプライ チェーンのリスクを軽減し、報告された脆弱性への迅速な対応を可能にします。 これには、データセットの出所、つまり AI アプリケーションに使用されたデータセットの詳細な履歴の維持が含まれます。履歴には、データセットのソースに関する情報だけでなく、変更内容の完全な記録も含まれる場合があります。 | E3: https://atlas.mitre.org/mitigations/AML.M0023 | F3: 45728 | G3: 45728
A4: AML.M0017 | B4: course-of-action--0ecbe6e0-865e-439c-925b-da558632bda6 | C4: AI モデルの配布方法 | D4: AI モデルをエッジ デバイスにデプロイすると、システムの攻撃対象領域が増大する可能性があります。敵対者がモデルにアクセスするレベルを下げるために、クラウド内でモデルを提供することを検討する必要があります。また、敵対者がモデルの前処理方法にアクセスできるグレー ボックス攻撃を防ぐために、クラウド内でのコンピューティング機能も検討する必要があります。 | E4: https://atlas.mitre.org/mitigations/AML.M0017 | F4: 45028 | G4: 45762
A5: AML.M0024 | B5: course-of-action--c887ee08-5448-41bb-a94a-e53bfedfa8b7 | C5: AI テレメトリのログ記録 | D5: デプロイされた AI モデルの入出力のログ記録を実装します。ログを監視することで、セキュリティ上の脅威を検出し、影響を軽減することができます。 さらに、ログ記録を有効にすると、検出を回避したい敵対者が AI リソースを利用するのを阻止できます。 | E5: https://atlas.mitre.org/mitigations/AML.M0024 | F5: 45728 | G5: 45761
A6: AML.M0015 | B6: course-of-action--99b7b032-7353-436b-a200-f52fca92cb11 | C6: 敵対的入力の検出 | D6: 既知の無害な動作から逸脱したり、以前の攻撃で観察された動作パターンを示したり、潜在的に悪意のある IP アドレスから送信されたりする敵対的な入力や異常なクエリーを検出してブロックします。AI モデルより前に、敵対的検出アルゴリズムを AI システムに組み込みます。 | E6: https://atlas.mitre.org/mitigations/AML.M0015 | F6: 45028 | G6: 45762
A7: AML.M0013 | B7: course-of-action--73e8d31a-5f48-4415-8f74-4f443a853050 | C7: コード署名 | D7: デジタル署名の検証によってバイナリとアプリケーションの整合性を強化し、信頼できないコードの実行を防ぎます。敵対者は AI ソフトウェアまたはモデルに悪意のあるコードを埋め込む可能性があります。コード署名の強化により、AI サプライ チェーンの侵害を防ぎ、悪意のあるコードの実行を防ぐことができます。 | E7: https://atlas.mitre.org/mitigations/AML.M0013 | F7: 45028 | G7: 45762
A8: AML.M0005 | B8: course-of-action--35a8cc31-c63d-4fb9-90c0-1dbba7bc724a | C8: 保存されている AI モデルとデータへのアクセスの制御 | D8: 内部のモデル レジストリへのアクセス制御を確立し、実稼働モデルへの内部アクセスを制限します。学習データへのアクセスは、承認されたユーザーのみに制限します。 | E8: https://atlas.mitre.org/mitigations/AML.M0005 | F8: 45028 | G8: 45762
A9: AML.M0019 | B9: course-of-action--8ec8b9e0-1934-4298-a1b3-f7c90bd9d864 | C9: 実稼働環境の AI モデルとデータへのアクセスの制御 | D9: 実稼働モデルにアクセスする前に、ユーザーに ID の検証を要求します。API エンドポイントの認証を要求し、実稼働モデルのクエリを監視して、使用ポリシーに準拠していることを確実にし、モデルの悪用を防止します。 | E9: https://atlas.mitre.org/mitigations/AML.M0019 | F9: 45303 | G9: 45762
A10: AML.M0012 | B10: course-of-action--633d5427-a2a6-4453-8675-7378e1b870e2 | C10: 機密情報の暗号化 | D10: AI モデルなどの機密データを暗号化して、機密データにアクセスを試みる敵対者から保護します。 | E10: https://atlas.mitre.org/mitigations/AML.M0012 | F10: 45028 | G10: 45762
A11: AML.M0020 | B11: course-of-action--ed266799-ad60-4515-a112-fb668d12cc07 | C11: 生成 AI ガードレール | D11: ガードレールとは、生成 AI モデルとユーザーと共有される出力の間に設置される安全対策であり、望ましくない入出力を防ぎます。ガードレールは、フィルター、ルールベース ロジック、正規表現などの検証ツールや、分類器や LLM の活用、固有表現抽出（NER）などの AI ベースのアプローチを用いて、プロンプトや応答の安全性を評価することができます。ドメイン固有の手法を用いることで、エチケット、ブランド毀損、脱獄、偽情報、コード エクスプロイト、SQL インジェクション、データ漏洩など、様々な分野におけるリスクを軽減できます。 | E11: https://atlas.mitre.org/mitigations/AML.M0020 | F11: 45728 | G11: 45728
A12: AML.M0021 | B12: course-of-action--e0135277-437f-4b2f-a2bd-66eee71c15e5 | C12: 生成 AI ガイドライン | D12: ガイドラインとは、ユーザー入力と生成 AIモ デルの間に配置され、モデルが望ましい出力を生成し、望ましくない出力を防止するための安全対策です。 ガイドラインは、すべてのユーザー プロンプトに指示を追加する形で実装することも、システム プロンプト内の指示の一部として実装することもできます。ガイドラインは、システムの目標、役割、意思を定義し、安全性とセキュリティに関するパラメータの概要を示すことができます。 | E12: https://atlas.mitre.org/mitigations/AML.M0021 | F12: 45728 | G12: 45728
A13: AML.M0022 | B13: course-of-action--b45ca9a8-2fe5-467b-b431-b9214c4f3e9b | C13: 生成 AI モデルの整合性（アライメント） | D13: 生成 AI モデルを学習または微調整する際には、安全性、セキュリティ、コンテンツ ポリシーとのモデルの整合性（アライメント）を改善する手法を活用することが重要です。 微調整プロセスにより、生成 AI モデルに組み込まれた安全機構が削除される可能性がありますが、教師ありの微調整、人間からのフィードバックまたは AI フィードバックからの強化学習、対象を絞った安全性コンテキスト蒸留などの手法を利用することで、モデルの安全性と整合性（アライメント）を向上させることができます。 | E13: https://atlas.mitre.org/mitigations/AML.M0022 | F13: 45728 | G13: 45728
... A33: AML.M0016 | B33: course-of-action--ff8b3c2e-aeab-4d66-a7bf-86058bb77ed3 | C33: 脆弱性スキャン | D33: 脆弱性スキャンは、潜在的に悪用される可能性のあるソフトウェアの脆弱性を発見し、修正するために使用されます。 AI モデルの保存に一般的に使用される pickle ファイルなどのファイル形式には、任意のコード実行を可能にするエクスプロイトが含まれている可能性があります。これらのファイルは、コードの実行、新しいプロセスの作成、ネットワーク機能の確立に使用される可能性のある潜在的に安全でない呼び出しがないかスキャンする必要があります。敵対者は、モデルが破損したファイルに悪意のあるコードを埋め込む可能性があるため、スキャナーは完全にデシリアライズできないモデルでも動作できる必要があります。モデル アーティファクトと、モデルによって生成されるダウン ストリーム製品の両方に対して、既知の脆弱性がないかスキャンする必要があります。 | E33: https://atlas.mitre.org/mitigations/AML.M0016 | F33: 45028 | G33: 45768

Sheet matrix (ja)
A1: ='tactics (ja)'!C16 -> 偵察 | C1: ='tactics (ja)'!C17 -> リソースの開発 | E1: ='tactics (ja)'!C12 -> 初期アクセス | G1: ='tactics (ja)'!C3 -> AI モデルへのアクセス | H1: ='tactics (ja)'!C9 -> 実行 | J1: ='tactics (ja)'!C14 -> 永続化 | L1: ='tactics (ja)'!C15 -> 権限昇格 | M1: ='tactics (ja)'!C7 -> 防御策の回避 | O1: ='tactics (ja)'!C6 -> 資格情報へのアクセス | P1: ='tactics (ja)'!C8 -> 探索 | R1: 水平展開 | S1: ='tactics (ja)'!C4 -> 収集 | T1: ='tactics (ja)'!C2 -> AI 攻撃のステージング | V1: ='tactics (ja)'!C5 -> コマンド＆コントロール | W1: ='tactics (ja)'!C10 -> 持出し | Y1: ='tactics (ja)'!C11 -> 影響
A2: ='techniques (ja)'!C15 -> 能動的なスキャン | C2: ='techniques (ja)'!C12 -> インフラストラクチャの獲得 | D2: ='techniques (ja)'!C6 -> AI 開発のワークスペース | E2: ='techniques (ja)'!C10 -> AI サプライ チェーンの侵害 | F2: ='techniques (ja)'!C9 -> AI ソフトウェア | G2: ='techniques (ja)'!C8 -> AI モデルの推論 API へのアクセス | H2: ='techniques (ja)'!C23 -> コマンドおよびスクリプト インタープリター | J2: ='techniques (ja)'!C81 -> LLM プロンプトの自己複製 | L2: ='techniques (ja)'!C77 -> LLM の脱獄 | M2: ='techniques (ja)'!C26 -> AI モデルの破損 | O2: ='techniques (ja)'!C134 -> セキュリティ上問題のある資格情報 | P2: ='techniques (ja)'!C22 -> クラウド サービスの探索 | S2: ='techniques (ja)'!C5 -> AI アーティファクトの収集 | T2: ='techniques (ja)'!C28 -> 敵対的データの作成 | U2: ='techniques (ja)'!C19 -> ブラック ボックス最適化 | V2: ='techniques (ja)'!C112 -> リバース シェル | W2: ='techniques (ja)'!C56 -> AI の推論 API による流出 | X2: ='techniques (ja)'!C60 -> AI モデルの抽出 | Y2: ='techniques (ja)'!C27 -> コスト ハーベスティング
A3: ='techniques (ja)'!C65 -> RAG インデックス化された対象の収集 | D3: ='techniques (ja)'!C24 -> 消費者向けハードウェア | F3: ='techniques (ja)'!C31 -> データ | G3: ='techniques (ja)'!C11 -> AI 対応の製品やサービス | H3: ='techniques (ja)'!#REF! -> #REF! | J3: ='techniques (ja)'!C85 -> AI モデルの操作 | K3: ='techniques (ja)'!C93 -> AI モデルのアーキテクチャの改変 | L3: ='techniques (ja)'!#REF! -> #REF! | M3: ='techniques (ja)'!C54 -> AI モデルの回避 | P3: ='techniques (ja)'!C41 -> AI アーティファクトの探索 | S3: ='techniques (ja)'!C33 -> 情報リポジトリのデータ | U3: ='techniques (ja)'!C20 -> ブラック ボックス転送 | X3: ='techniques (ja)'!C72 -> 学習データのメンバーシップ推論 | Y3: ='techniques (ja)'!C37 -> AI サービスへの運用妨害
A4: ='techniques (ja)'!C113 -> アプリケーション リポジトリの検索 | C4: ='techniques (ja)'!C13 -> 公開されている AI アーティファクトの獲得 | D4: ='techniques (ja)'!C35 -> データセット | F4: ='techniques (ja)'!C69 -> ハードウェア | G4: ='techniques (ja)'!C64 -> AI モデルへの完全なアクセス | H4: ='techniques (ja)'!C79 -> LLM プロンプト インジェクション | I4: ='techniques (ja)'!C39 -> 直接（インジェクション） | K4: ='techniques (ja)'!C99 -> AI モデルの汚染 | M4: ='techniques (ja)'!C62 -> 偽 RAG エントリ インジェクション | N4: ='techniques (ja)'!C21 -> 引用 | P4: ='techniques (ja)'!C42 -> AI モデル ファミリーの探索 | S4: ='techniques (ja)'!C34 -> ローカル システムのデータ | U4: ='techniques (ja)'!C73 -> バックドア トリガーの挿入 | X4: ='techniques (ja)'!C74 -> AI モデルの反転 | Y4: ='techniques (ja)'!C51 -> AI モデルの整合性の侵害
A5: ='techniques (ja)'!C114 -> AI の脆弱性に関する公開されている分析結果の検索 | D5: ='techniques (ja)'!C91 -> モデル（注: 原文では Models） | F5: ='techniques (ja)'!C90 -> モデル（注: 原文では Model） | G5: ='techniques (ja)'!C98 -> 物理環境へのアクセス | I5: ='techniques (ja)'!C71 -> 間接（インジェクション） | J5: ='techniques (ja)'!C100 -> 学習データの汚染 | N5: ='techniques (ja)'!C25 -> コンテナ レジストリ | P5: ='techniques (ja)'!C43 -> AI モデルのオントロジーの探索 | U5: ='techniques (ja)'!C87 -> 手動による変更 | W5: ='techniques (ja)'!C57 -> サイバー手段による流出 | Y5: ='techniques (ja)'!C52 -> データセットの整合性の侵害 | Z5: ='techniques (ja)'!C84 -> 悪意のあるパッケージ
A6: ='techniques (ja)'!C115 -> 公開されている技術データベースの検索 | B6: ='techniques (ja)'!C75 -> 定期刊行物やカンファレンス議事録 | C6: ='techniques (ja)'!C38 -> 機能の開発 | D6: ='techniques (ja)'!C17 -> AI への敵対的攻撃 | E6: ='techniques (ja)'!C48 -> ドライブ バイによる侵害 | H6: ='techniques (ja)'!C137 -> ユーザーによる実行 | I6: ='techniques (ja)'!C133 -> 安全でない AI アーティファクト | J6: ='techniques (ja)'!C109 -> RAG の汚染 | N6: ='techniques (ja)'!C49 -> マルウェアの埋め込み | P6: ='techniques (ja)'!C44 -> AI モデルの出力の探索 | Q6: ='techniques (ja)'!C68 -> 生成 AI | U6: ='techniques (ja)'!C141 -> ホワイト ボックス最適化 | W6: ='techniques (ja)'!C61 -> LLM システム プロンプトの抽出 | Y6: ='techniques (ja)'!C54 -> AI モデルの回避
B7: ='techniques (ja)'!C101 -> プレプリント リポジトリ | C7: ='techniques (ja)'!C53 -> アカウントの確立 | E7: ='techniques (ja)'!C54 -> AI モデルの回避 | M7: ='techniques (ja)'!C70 -> なりすまし | P7: ='techniques (ja)'!C45 -> LLM の幻覚の探索 | Q7: ='techniques (ja)'!C47 -> ドメイン | T7: ='techniques (ja)'!C29 -> プロキシー AI モデルの作成 | U7: ='techniques (ja)'!C130 -> 収集した AI アーティファクトによるプロキシーの学習 | W7: ='techniques (ja)'!C76 -> LLM からのデータ漏洩 | Y7: ='techniques (ja)'!C59 -> 外部への危害 | Z7: ='techniques (ja)'!C7 -> AI 知的財産の窃取
B8: ='techniques (ja)'!C127 -> 技術ブログ | C8: ='techniques (ja)'!C78 -> LLM プロンプトの作成 | E8: ='techniques (ja)'!C58 -> 公開アプリケーションの悪用 | M8: ='techniques (ja)'!C77 -> LLM の脱獄 | Q8: ='techniques (ja)'!C97 -> 物理的な対抗手段 | U8: ='techniques (ja)'!C131 -> レプリケーションによるプロキシーの学習 | W8: ='techniques (ja)'!C82 -> LLM 応答のレンダリング | X8: ='techniques (ja)'!C118 -> サーバーレス | Z8: ='techniques (ja)'!C63 -> 財務的損害
A9: ='techniques (ja)'!C117 -> 被害者が所有するウェブサイトの検索 | C9: ='techniques (ja)'!C95 -> 機能の獲得 | D9: ='techniques (ja)'!C16 -> AI への敵対的攻撃の実装 | E9: ='techniques (ja)'!C96 -> フィッシング | F9: ='techniques (ja)'!C122 -> LLM ソーシャル エンジニアリングによるスピア フィッシング | M9: ='techniques (ja)'!C80 -> LLM プロンプトの難読化 | P9: ='techniques (ja)'!C46 -> LLM のシステム情報の探索 | Q9: ='techniques (ja)'!C123 -> 特殊文字セット | U9: ='techniques (ja)'!C136 -> 学習済みモデルの使用 | Z9: ='techniques (ja)'!C110 -> 風評被害
D10: ='techniques (ja)'!C120 -> ソフトウェア ツール | E10: ='techniques (ja)'!C139 -> 有効なアカウント | M10: ='techniques (ja)'!C83 -> LLM からの信頼された出力コンポーネントの操作 | Q10: ='techniques (ja)'!C125 -> システム命令に関するキーワード | T10: ='techniques (ja)'!C85 -> AI モデルの操作 | U10: ='techniques (ja)'!C93 -> AI モデルのアーキテクチャの改変 | Z10: ='techniques (ja)'!C119 -> 社会的損害
C11: ='techniques (ja)'!C100 -> 学習データの汚染 | M11: ='techniques (ja)'!C88 -> マスカレード | Q11: ='techniques (ja)'!C126 -> システム プロンプト | U11: ='techniques (ja)'!C99 -> AI モデルの汚染 | Z11: ='techniques (ja)'!C138 -> ユーザー被害
C12: ='techniques (ja)'!C104 -> 幻覚化されたエンティティの公開 | T12: ='techniques (ja)'!C140 -> 攻撃の検証 | Y12: ='techniques (ja)'!C121 -> AI システムに対するチャフ データを使用したスパム攻撃
C13: ='techniques (ja)'!C105 -> 汚染済みデータセットの公開
C14: ='techniques (ja)'!C106 -> 汚染済みモデルの公開
C15: ='techniques (ja)'!C111 -> 検索コンテンツの作成
C16: ='techniques (ja)'!C124 -> 機能のステージング
